<?xml version="1.0" ?>
<robot name="articulation" xmlns:xacro="http://www.ros.org/wiki/xacro">

<xacro:include filename="$(find articulation_description)/urdf/materials.xacro" />
<xacro:include filename="$(find articulation_description)/urdf/articulation.trans" />
<xacro:include filename="$(find articulation_description)/urdf/articulation.gazebo" />
<link name="base_link">
  <inertial>
    <origin xyz="-1.2272860191231992e-05 6.930542941604452e-07 0.02514924726159968" rpy="0 0 0"/>
    <mass value="0.3737549922804392"/>
    <inertia ixx="0.000618" iyy="0.000619" izz="0.000735" ixy="-0.0" iyz="0.0" ixz="-0.0"/>
  </inertial>
  <visual>
    <origin xyz="0 0 0" rpy="0 0 0"/>
    <geometry>
      <mesh filename="package://articulation_description/meshes/base_link.stl" scale="0.001 0.001 0.001"/>
    </geometry>
    <material name="gray"/>
  </visual>
  <collision>
    <origin xyz="0 0 0" rpy="0 0 0"/>
    <geometry>
      <mesh filename="package://articulation_description/meshes/base_link.stl" scale="0.001 0.001 0.001"/>
    </geometry>
  </collision>
</link>

<link name="Link_0_v4_1">
  <inertial>
    <origin xyz="0.0004165585996347492 -1.2682253631437242e-05 0.0014097138461642983" rpy="0 0 0"/>
    <mass value="0.05203854090410597"/>
    <inertia ixx="2.4e-05" iyy="2.6e-05" izz="4.6e-05" ixy="0.0" iyz="-0.0" ixz="-0.0"/>
  </inertial>
  <visual>
    <origin xyz="-0.0 -0.0 -0.08" rpy="0 0 0"/>
    <geometry>
      <mesh filename="package://articulation_description/meshes/Link_0_v4_1.stl" scale="0.001 0.001 0.001"/>
    </geometry>
    <material name="white"/>
  </visual>
  <collision>
    <origin xyz="-0.0 -0.0 -0.08" rpy="0 0 0"/>
    <geometry>
      <mesh filename="package://articulation_description/meshes/Link_0_v4_1.stl" scale="0.001 0.001 0.001"/>
    </geometry>
  </collision>
</link>

<joint name="Revolute_2" type="revolute">
  <origin xyz="0.0 0.0 0.08" rpy="0 0 0"/>
  <parent link="base_link"/>
  <child link="Link_0_v4_1"/>
  <axis xyz="-0.0 -0.0 1.0"/>
  <limit upper="6.283185" lower="0.0" effort="100" velocity="100"/>
</joint>

</robot>
